Workbook

Sheet Daftar Fitur
B1: Total Modul | C1: Total Fitur | E1: Total Biaya | F1: Total Biaya | G1: Total Pengajuan
B2: =COUNTA(B5:B140) -> 13 | C2: =COUNTA(C5:C140) -> 119 | D2: =COUNTA(D5:D140) -> 119 | E2: =sum(E5:E140) -> 902000000 | F2: =sum(F5:F140) -> 902000000 | G2: =if(G5=1,F5,0)+if(G13=1,F13,0)+if(G24=1,F24,0)+if(G35=1,F35,0)+if(G48=1,F48,0)+if(G53=1,F53,0)+if(G74=1,F74,0)+if(G83=1,F83,0)+if(G93=1,F93,0)+if(G98=1,F98,0)+if(G111=1,F111,0)+if(G116=1,F116,0)+if(G117=1,F117,0) -> 525000000
H3: Persentase Biaya | I3: 0.05 | J3: 0.1 | K3: 0.65 | L3: 0.2
A4: Column 1 | B4: Modul | C4: Fitur | D4: Fungsi | E4: Biaya | F4: Biaya Per Modul | G4: Yang Diajukan ke RIIM Kompetisi | H4: Tahun ke | I4: Biaya Pembuatan Model | J4: Biaya Pembuatan Arsitektur | K4: Biaya Pembuatan MVP | L4: Biaya Penyempurnaan Platform | N4: Fungsi | O4: Biaya (Talent + Tools)
B5: Komunitas | C5: - Pencarian komunitas | D5: Read | E5: =ifs(D5=$N$5, $O$5, D5=$N$6, $O$6, D5=$N$7, $O$7, D5=$N$8, $O$8, D5=$N$9, $O$9) -> 7000000 | F5: =sum(E5:E12) -> 51000000 | G5: 1 | H5: 1 | I5: =$I$3*E5 -> 350000 | J5: =$J$3*E5 -> 700000 | K5: =$K$3*E5 -> 4550000 | L5: =$L$3*E5 -> 1400000 | N5: Create | O5: 5000000
C6: - Daftar komunitas | D6: Read | E6: =ifs(D6=$N$5, $O$5, D6=$N$6, $O$6, D6=$N$7, $O$7, D6=$N$8, $O$8, D6=$N$9, $O$9) -> 7000000 | I6: =$I$3*E6 -> 350000 | J6: =$J$3*E6 -> 700000 | K6: =$K$3*E6 -> 4550000 | L6: =$L$3*E6 -> 1400000 | N6: Read | O6: 7000000
C7: - Profil komunitas | D7: Read | E7: =ifs(D7=$N$5, $O$5, D7=$N$6, $O$6, D7=$N$7, $O$7, D7=$N$8, $O$8, D7=$N$9, $O$9) -> 7000000 | I7: =$I$3*E7 -> 350000 | J7: =$J$3*E7 -> 700000 | K7: =$K$3*E7 -> 4550000 | L7: =$L$3*E7 -> 1400000 | N7: Update | O7: 3000000
C8: - Integrasi sosial media | D8: Read | E8: =ifs(D8=$N$5, $O$5, D8=$N$6, $O$6, D8=$N$7, $O$7, D8=$N$8, $O$8, D8=$N$9, $O$9) -> 7000000 | I8: =$I$3*E8 -> 350000 | J8: =$J$3*E8 -> 700000 | K8: =$K$3*E8 -> 4550000 | L8: =$L$3*E8 -> 1400000 | N8: Delete | O8: 3000000
C9: - Membuat komunitas | D9: Create | E9: =ifs(D9=$N$5, $O$5, D9=$N$6, $O$6, D9=$N$7, $O$7, D9=$N$8, $O$8, D9=$N$9, $O$9) -> 5000000 | I9: =$I$3*E9 -> 250000 | J9: =$J$3*E9 -> 500000 | K9: =$K$3*E9 -> 3250000 | L9: =$L$3*E9 -> 1000000 | N9: Read & Create | O9: 12000000
C10: - Perbarui komunitas | D10: Update | E10: =ifs(D10=$N$5, $O$5, D10=$N$6, $O$6, D10=$N$7, $O$7, D10=$N$8, $O$8, D10=$N$9, $O$9) -> 3000000 | I10: =$I$3*E10 -> 150000 | J10: =$J$3*E10 -> 300000 | K10: =$K$3*E10 -> 1950000 | L10: =$L$3*E10 -> 600000
C11: - Hapus komunitas | D11: Delete | E11: =ifs(D11=$N$5, $O$5, D11=$N$6, $O$6, D11=$N$7, $O$7, D11=$N$8, $O$8, D11=$N$9, $O$9) -> 3000000 | I11: =$I$3*E11 -> 150000 | J11: =$J$3*E11 -> 300000 | K11: =$K$3*E11 -> 1950000 | L11: =$L$3*E11 -> 600000
C12: - Analitik keaktifan komunitas | D12: Read & Create | E12: =ifs(D12=$N$5, $O$5, D12=$N$6, $O$6, D12=$N$7, $O$7, D12=$N$8, $O$8, D12=$N$9, $O$9) -> 12000000 | I12: =$I$3*E12 -> 600000 | J12: =$J$3*E12 -> 1200000 | K12: =$K$3*E12 -> 7800000 | L12: =$L$3*E12 -> 2400000
B13: Keanggotaan | C13: - Pengaturan pendaftaran anggota baru | D13: Create | E13: =ifs(D13=$N$5, $O$5, D13=$N$6, $O$6, D13=$N$7, $O$7, D13=$N$8, $O$8, D13=$N$9, $O$9) -> 5000000 | F13: =sum(E13:E23) -> 88000000 | G13: 1 | H13: 1 | I13: =$I$3*E13 -> 250000 | J13: =$J$3*E13 -> 500000 | K13: =$K$3*E13 -> 3250000 | L13: =$L$3*E13 -> 1000000
C14: - Undangan keanggotaan | D14: Create | E14: =ifs(D14=$N$5, $O$5, D14=$N$6, $O$6, D14=$N$7, $O$7, D14=$N$8, $O$8, D14=$N$9, $O$9) -> 5000000 | I14: =$I$3*E14 -> 250000 | J14: =$J$3*E14 -> 500000 | K14: =$K$3*E14 -> 3250000 | L14: =$L$3*E14 -> 1000000
C15: - Pendaftaran anggota baru | D15: Read & Create | E15: =ifs(D15=$N$5, $O$5, D15=$N$6, $O$6, D15=$N$7, $O$7, D15=$N$8, $O$8, D15=$N$9, $O$9) -> 12000000 | I15: =$I$3*E15 -> 600000 | J15: =$J$3*E15 -> 1200000 | K15: =$K$3*E15 -> 7800000 | L15: =$L$3*E15 -> 2400000
C16: - Seleksi anggota | D16: Read & Create | E16: =ifs(D16=$N$5, $O$5, D16=$N$6, $O$6, D16=$N$7, $O$7, D16=$N$8, $O$8, D16=$N$9, $O$9) -> 12000000 | I16: =$I$3*E16 -> 600000 | J16: =$J$3*E16 -> 1200000 | K16: =$K$3*E16 -> 7800000 | L16: =$L$3*E16 -> 2400000
C17: - Aktifitas anggota | D17: Read & Create | E17: =ifs(D17=$N$5, $O$5, D17=$N$6, $O$6, D17=$N$7, $O$7, D17=$N$8, $O$8, D17=$N$9, $O$9) -> 12000000 | I17: =$I$3*E17 -> 600000 | J17: =$J$3*E17 -> 1200000 | K17: =$K$3*E17 -> 7800000 | L17: =$L$3*E17 -> 2400000
C18: - Profil anggota | D18: Read | E18: =ifs(D18=$N$5, $O$5, D18=$N$6, $O$6, D18=$N$7, $O$7, D18=$N$8, $O$8, D18=$N$9, $O$9) -> 7000000 | I18: =$I$3*E18 -> 350000 | J18: =$J$3*E18 -> 700000 | K18: =$K$3*E18 -> 4550000 | L18: =$L$3*E18 -> 1400000
C19: - Perbarui keanggotaan | D19: Update | E19: =ifs(D19=$N$5, $O$5, D19=$N$6, $O$6, D19=$N$7, $O$7, D19=$N$8, $O$8, D19=$N$9, $O$9) -> 3000000 | I19: =$I$3*E19 -> 150000 | J19: =$J$3*E19 -> 300000 | K19: =$K$3*E19 -> 1950000 | L19: =$L$3*E19 -> 600000
C20: - Hapus keanggotaan | D20: Delete | E20: =ifs(D20=$N$5, $O$5, D20=$N$6, $O$6, D20=$N$7, $O$7, D20=$N$8, $O$8, D20=$N$9, $O$9) -> 3000000 | I20: =$I$3*E20 -> 150000 | J20: =$J$3*E20 -> 300000 | K20: =$K$3*E20 -> 1950000 | L20: =$L$3*E20 -> 600000
C21: - Analitik keaktifan anggota | D21: Read & Create | E21: =ifs(D21=$N$5, $O$5, D21=$N$6, $O$6, D21=$N$7, $O$7, D21=$N$8, $O$8, D21=$N$9, $O$9) -> 12000000 | I21: =$I$3*E21 -> 600000 | J21: =$J$3*E21 -> 1200000 | K21: =$K$3*E21 -> 7800000 | L21: =$L$3*E21 -> 2400000
C22: - Integrasi news feed | D22: Create | E22: =ifs(D22=$N$5, $O$5, D22=$N$6, $O$6, D22=$N$7, $O$7, D22=$N$8, $O$8, D22=$N$9, $O$9) -> 5000000 | I22: =$I$3*E22 -> 250000 | J22: =$J$3*E22 -> 500000 | K22: =$K$3*E22 -> 3250000 | L22: =$L$3*E22 -> 1000000
C23: - Interaksi news feed | D23: Read & Create | E23: =ifs(D23=$N$5, $O$5, D23=$N$6, $O$6, D23=$N$7, $O$7, D23=$N$8, $O$8, D23=$N$9, $O$9) -> 12000000 | I23: =$I$3*E23 -> 600000 | J23: =$J$3*E23 -> 1200000 | K23: =$K$3*E23 -> 7800000 | L23: =$L$3*E23 -> 2400000
B24: Kepengurusan | C24: - Pengaturan bentuk kepengurusan | D24: Create | E24: =ifs(D24=$N$5, $O$5, D24=$N$6, $O$6, D24=$N$7, $O$7, D24=$N$8, $O$8, D24=$N$9, $O$9) -> 5000000 | F24: =sum(E24:E34) -> 99000000 | G24: 1 | H24: 1 | I24: =$I$3*E24 -> 250000 | J24: =$J$3*E24 -> 500000 | K24: =$K$3*E24 -> 3250000 | L24: =$L$3*E24 -> 1000000
C25: - Pengaturan kepengurusan | D25: Read & Create | E25: =ifs(D25=$N$5, $O$5, D25=$N$6, $O$6, D25=$N$7, $O$7, D25=$N$8, $O$8, D25=$N$9, $O$9) -> 12000000 | I25: =$I$3*E25 -> 600000 | J25: =$J$3*E25 -> 1200000 | K25: =$K$3*E25 -> 7800000 | L25: =$L$3*E25 -> 2400000
C26: - Struktur kepengurusan | D26: Read | E26: =ifs(D26=$N$5, $O$5, D26=$N$6, $O$6, D26=$N$7, $O$7, D26=$N$8, $O$8, D26=$N$9, $O$9) -> 7000000 | I26: =$I$3*E26 -> 350000 | J26: =$J$3*E26 -> 700000 | K26: =$K$3*E26 -> 4550000 | L26: =$L$3*E26 -> 1400000
C27: - Profil kepengurusan | D27: Read | E27: =ifs(D27=$N$5, $O$5, D27=$N$6, $O$6, D27=$N$7, $O$7, D27=$N$8, $O$8, D27=$N$9, $O$9) -> 7000000 | I27: =$I$3*E27 -> 350000 | J27: =$J$3*E27 -> 700000 | K27: =$K$3*E27 -> 4550000 | L27: =$L$3*E27 -> 1400000
C28: - Pengaturan pemilihan ketua | D28: Create | E28: =ifs(D28=$N$5, $O$5, D28=$N$6, $O$6, D28=$N$7, $O$7, D28=$N$8, $O$8, D28=$N$9, $O$9) -> 5000000 | I28: =$I$3*E28 -> 250000 | J28: =$J$3*E28 -> 500000 | K28: =$K$3*E28 -> 3250000 | L28: =$L$3*E28 -> 1000000
C29: - Pemilihan ketua | D29: Read & Create | E29: =ifs(D29=$N$5, $O$5, D29=$N$6, $O$6, D29=$N$7, $O$7, D29=$N$8, $O$8, D29=$N$9, $O$9) -> 12000000 | I29: =$I$3*E29 -> 600000 | J29: =$J$3*E29 -> 1200000 | K29: =$K$3*E29 -> 7800000 | L29: =$L$3*E29 -> 2400000
C30: - Pendaftaran kepengurusan | D30: Read & Create | E30: =ifs(D30=$N$5, $O$5, D30=$N$6, $O$6, D30=$N$7, $O$7, D30=$N$8, $O$8, D30=$N$9, $O$9) -> 12000000 | I30: =$I$3*E30 -> 600000 | J30: =$J$3*E30 -> 1200000 | K30: =$K$3*E30 -> 7800000 | L30: =$L$3*E30 -> 2400000
C31: - Pemilihan kepengurusan | D31: Read & Create | E31: =ifs(D31=$N$5, $O$5, D31=$N$6, $O$6, D31=$N$7, $O$7, D31=$N$8, $O$8, D31=$N$9, $O$9) -> 12000000 | I31: =$I$3*E31 -> 600000 | J31: =$J$3*E31 -> 1200000 | K31: =$K$3*E31 -> 7800000 | L31: =$L$3*E31 -> 2400000
C32: - Pergantian pengurus (serah terima jabatan) | D32: Read & Create | E32: =ifs(D32=$N$5, $O$5, D32=$N$6, $O$6, D32=$N$7, $O$7, D32=$N$8, $O$8, D32=$N$9, $O$9) -> 12000000 | I32: =$I$3*E32 -> 600000 | J32: =$J$3*E32 -> 1200000 | K32: =$K$3*E32 -> 7800000 | L32: =$L$3*E32 -> 2400000
C33: - Perbarui kepengurusan | D33: Update | E33: =ifs(D33=$N$5, $O$5, D33=$N$6, $O$6, D33=$N$7, $O$7, D33=$N$8, $O$8, D33=$N$9, $O$9) -> 3000000 | I33: =$I$3*E33 -> 150000 | J33: =$J$3*E33 -> 300000 | K33: =$K$3*E33 -> 1950000 | L33: =$L$3*E33 -> 600000
C34: - Analitik keaktifan kepengurusan | D34: Read & Create | E34: =ifs(D34=$N$5, $O$5, D34=$N$6, $O$6, D34=$N$7, $O$7, D34=$N$8, $O$8, D34=$N$9, $O$9) -> 12000000 | I34: =$I$3*E34 -> 600000 | J34: =$J$3*E34 -> 1200000 | K34: =$K$3*E34 -> 7800000 | L34: =$L$3*E34 -> 2400000
B35: Event management | C35: - Pengaturan event | D35: Create | E35: =ifs(D35=$N$5, $O$5, D35=$N$6, $O$6, D35=$N$7, $O$7, D35=$N$8, $O$8, D35=$N$9, $O$9) -> 5000000 | F35: =sum(E35:E47) -> 101000000 | G35: 1 | H35: 1 | I35: =$I$3*E35 -> 250000 | J35: =$J$3*E35 -> 500000 | K35: =$K$3*E35 -> 3250000 | L35: =$L$3*E35 -> 1000000
C36: - Promosi event | D36: Read | E36: =ifs(D36=$N$5, $O$5, D36=$N$6, $O$6, D36=$N$7, $O$7, D36=$N$8, $O$8, D36=$N$9, $O$9) -> 7000000 | I36: =$I$3*E36 -> 350000 | J36: =$J$3*E36 -> 700000 | K36: =$K$3*E36 -> 4550000 | L36: =$L$3*E36 -> 1400000
C37: - Pendaftaran event | D37: Read & Create | E37: =ifs(D37=$N$5, $O$5, D37=$N$6, $O$6, D37=$N$7, $O$7, D37=$N$8, $O$8, D37=$N$9, $O$9) -> 12000000 | I37: =$I$3*E37 -> 600000 | J37: =$J$3*E37 -> 1200000 | K37: =$K$3*E37 -> 7800000 | L37: =$L$3*E37 -> 2400000
C38: - Integrasi kalender | D38: Read | E38: =ifs(D38=$N$5, $O$5, D38=$N$6, $O$6, D38=$N$7, $O$7, D38=$N$8, $O$8, D38=$N$9, $O$9) -> 7000000 | I38: =$I$3*E38 -> 350000 | J38: =$J$3*E38 -> 700000 | K38: =$K$3*E38 -> 4550000 | L38: =$L$3*E38 -> 1400000
C39: - Attendance | D39: Read & Create | E39: =ifs(D39=$N$5, $O$5, D39=$N$6, $O$6, D39=$N$7, $O$7, D39=$N$8, $O$8, D39=$N$9, $O$9) -> 12000000 | I39: =$I$3*E39 -> 600000 | J39: =$J$3*E39 -> 1200000 | K39: =$K$3*E39 -> 7800000 | L39: =$L$3*E39 -> 2400000
C40: - Social media integration | D40: Read & Create | E40: =ifs(D40=$N$5, $O$5, D40=$N$6, $O$6, D40=$N$7, $O$7, D40=$N$8, $O$8, D40=$N$9, $O$9) -> 12000000 | I40: =$I$3*E40 -> 600000 | J40: =$J$3*E40 -> 1200000 | K40: =$K$3*E40 -> 7800000 | L40: =$L$3*E40 -> 2400000
...

Sheet Kebutuhan Biaya
K1: Double Check
B2: Tahun Riset | C2: Nama Modul | D2: Biaya Pembuatan Model | E2: Biaya Pembuatan Arsitektur | F2: Biaya Pembuatan MVP | G2: Biaya Penyempurnaan Pertama | H2: Biaya Penyempurnaan Kedua | I2: Total | K2: Total Keseluruhan Per Modul
B3: 1 | C3: Total | D3: =sum(D4:D11) -> 26250000 | E3: =sum(E4:E11) -> 52500000 | F3: =sum(F4:F11) -> 301600000 | I3: =sum(D3:H3) -> 380350000 | K3: =sum(K4:K11) -> 525000000
C4: ='Daftar Fitur'!B5 -> Komunitas | D4: =sum('Daftar Fitur'!I5:I12) -> 2550000 | E4: =sum('Daftar Fitur'!J5:J12) -> 5100000 | F4: =sum('Daftar Fitur'!K5:K12) -> 33150000 | K4: =D4+E4+F4+G13+H22 -> 51000000
C5: ='Daftar Fitur'!B13 -> Keanggotaan | D5: =sum('Daftar Fitur'!I13:I23) -> 4400000 | E5: =sum('Daftar Fitur'!J13:J23) -> 8800000 | F5: =sum('Daftar Fitur'!K13:K23) -> 57200000 | K5: =D5+E5+F5+G14+H23 -> 88000000
C6: ='Daftar Fitur'!B24 -> Kepengurusan | D6: =sum('Daftar Fitur'!I24:I34) -> 4950000 | E6: =sum('Daftar Fitur'!J24:J34) -> 9900000 | F6: =sum('Daftar Fitur'!K24:K34) -> 64350000 | K6: =D6+E6+F6+G15+H24 -> 99000000
C7: ='Daftar Fitur'!B35 -> Event management | D7: =sum('Daftar Fitur'!I35:I47) -> 5050000 | E7: =sum('Daftar Fitur'!J35:J47) -> 10100000 | F7: =sum('Daftar Fitur'!K35:K47) -> 65650000 | K7: =D7+E7+F7+G16+H25 -> 101000000
C8: ='Daftar Fitur'!B48 -> Sertifikat | D8: =sum('Daftar Fitur'!I48:I52) -> 2150000 | E8: =sum('Daftar Fitur'!J48:J52) -> 4300000 | F8: =sum('Daftar Fitur'!K48:K52) -> 27950000 | K8: =D8+E8+F8+G17+H26 -> 43000000
C9: =C18 -> Community Collaboration | D9: =sum('Daftar Fitur'!I83:I92) -> 4100000 | E9: =sum('Daftar Fitur'!J83:J92) -> 8200000 | F9: =sum('Daftar Fitur'!K83:K92) -> 53300000 | K9: =D9+E9+F9+G18+H27 -> 82000000
C10: =C19 -> Dashboard Analitik | D10: ='Daftar Fitur'!I116 -> 600000 | E10: ='Daftar Fitur'!J116 -> 1200000 | K10: =D10+E10+F19+G19+H28 -> 12000000
C11: =C20 -> Fasilitator (AI) | D11: =sum('Daftar Fitur'!I117:I123) -> 2450000 | E11: =sum('Daftar Fitur'!J117:J123) -> 4900000 | K11: =D11+E11+F20+G20+H29 -> 49000000
B12: 2 | C12: Total | F12: =sum(F13:F20) -> 39650000 | G12: =sum(G13:G20) -> 52500000 | I12: =sum(D12:H12) -> 92150000
C13: =C4 -> Komunitas | G13: =sum('Daftar Fitur'!L5:L12)/2 -> 5100000
C14: =C5 -> Keanggotaan | G14: =sum('Daftar Fitur'!L13:L23)/2 -> 8800000
C15: =C6 -> Kepengurusan | G15: =sum('Daftar Fitur'!L24:L34)/2 -> 9900000
C16: =C7 -> Event management | G16: =sum('Daftar Fitur'!L35:L47)/2 -> 10100000
C17: =C8 -> Sertifikat | G17: =sum('Daftar Fitur'!L48:L52)/2 -> 4300000
C18: ='Daftar Fitur'!B83 -> Community Collaboration | G18: =sum('Daftar Fitur'!L83:L92)/2 -> 8200000
C19: Dashboard Analitik | F19: ='Daftar Fitur'!K116 -> 7800000 | G19: ='Daftar Fitur'!L116/2 -> 1200000
C20: ='Daftar Fitur'!B117 -> Fasilitator (AI) | F20: =sum('Daftar Fitur'!K117:K123) -> 31850000 | G20: =sum('Daftar Fitur'!L117:L123)/2 -> 4900000
B21: 3 | C21: Total | H21: =sum(H22:H29) -> 52500000 | I21: =sum(D21:H21) -> 52500000
C22: =C13 -> Komunitas | H22: =sum('Daftar Fitur'!L5:L12)/2 -> 5100000
C23: =C14 -> Keanggotaan | H23: =sum('Daftar Fitur'!L13:L23)/2 -> 8800000
C24: =C15 -> Kepengurusan | H24: =sum('Daftar Fitur'!L24:L34)/2 -> 9900000
C25: =C16 -> Event management | H25: =sum('Daftar Fitur'!L35:L47)/2 -> 10100000
C26: =C17 -> Sertifikat | H26: =sum('Daftar Fitur'!L48:L52)/2 -> 4300000
C27: =C18 -> Community Collaboration | H27: =sum('Daftar Fitur'!L83:L92)/2 -> 8200000
C28: Dashboard Analitik | H28: ='Daftar Fitur'!L116/2 -> 1200000
C29: =C20 -> Fasilitator (AI) | H29: =sum('Daftar Fitur'!L117:L123)/2 -> 4900000
B30: Total Pengajuan | I30: =I3+I12+I21 -> 525000000

Sheet Arsip Kebutuhan Biaya 
B3: Kebutuhan | C3: Deskripsi | D3: Keluaran | E3: Jumlah | F3: Harga (Tax Inc) | G3: Biaya Bulanan | H3: Biaya Tahunan | I3: Biaya Tiga Tahun
B4: Keseluruhan | G4: =G5+G11 -> 54300000 | H4: =G4*12 -> 651600000 | I4: =H4*3 -> 1954800000
B5: Biaya Langsung Personil | C5: Anggota riset | G5: =sum(G6:G10) -> 12000000 | H5: =G5*12 -> 144000000 | I5: =H5*3 -> 432000000 | J5: =G5/G4 -> 0.22099448
B6: Product Manager | C6: Membangun rencana riset produk berdasarkan kebutuhan pasar | D6: Dokumen: PRD, Analisa feedback | E6: 1 | F6: 2400000 | G6: =E6*F6 -> 2400000 | H6: =G6*12 -> 28800000 | I6: =H6*3 -> 86400000
B7: Junior UXUI Designer | C7: Merancang UX dan UI berdasarkan PRD | D7: Prototype: User flow, prototype, user interface | E7: 1 | F7: 2400000 | G7: =E7*F7 -> 2400000 | H7: =G7*12 -> 28800000 | I7: =H7*3 -> 86400000
B8: Junior Front End Engineer | C8: Membangun kode front end dan integrasi API | D8: Implementasi: aplikasi | E8: 1 | F8: 2400000 | G8: =E8*F8 -> 2400000 | H8: =G8*12 -> 28800000 | I8: =H8*3 -> 86400000
B9: Senior Backend Engineer | C9: Membangun kode back end, database, dan instalasi ke server | D9: Implementasi: aplikasi | E9: 1 | F9: 2400000 | G9: =E9*F9 -> 2400000 | H9: =G9*12 -> 28800000 | I9: =H9*3 -> 86400000
B10: Junior QA Engineer | C10: Mengelola uji produk dari perencanaan, perancangan, eksekusi, hingga rilis | D10: Dokumen: test execution report, release report | E10: 1 | F10: 2400000 | G10: =E10*F10 -> 2400000 | H10: =G10*12 -> 28800000 | I10: =H10*3 -> 86400000
B11: Biaya Langsung Non-Personil | G11: =G12+G39+G42 -> 42300000 | H11: =H12+H39+H42 -> 507600000 | I11: =I12+I39+I42 -> 1522800000 | J11: =G11/G4 -> 0.77900552
B12: Sewa Alat | C12: Berdasarkan pengguna | G12: =sum(G14,G20,G24,G29,G33)*20000+G36 -> 42300000 | H12: =G12*12 -> 507600000 | I12: =H12*3 -> 1522800000
B13: Tools in Dollars | G13: =sum(G14,G20,G24,G29,G33) -> 2040 | H13: =G13*12 -> 24480 | I13: =H13*3 -> 73440
B14: Product Manager | G14: =sum(G15:G19) -> 485 | H14: =G14*12 -> 5820 | I14: =H14*3 -> 17460
B15: Jira | C15: Kelola backlog, perencanaan sprint, pemantauan progres tiket | D15: Akses untuk semua anggota | E15: 7 | F15: 20 | G15: =E15*F15 -> 140 | H15: =G15*12 -> 1680 | I15: =H15*3 -> 5040
B16: Confluence | C16: Memusatkan dokumentasi produk | D16: Akses untuk semua anggota | E16: 7 | F16: 10 | G16: =15*7 -> 105 | H16: =G16*12 -> 1260 | I16: =H16*3 -> 3780
B17: Productboard | C17: Membuat produk roadmap dan menghubungkan umpan balik pengguna ke ide fitur | D17: Akses untuk PM | E17: 1 | F17: 20 | G17: =15*7 -> 105 | H17: =G17*12 -> 1260 | I17: =H17*3 -> 3780
B18: Chat PRD | C18: Membuat PRD berdasarkan kebutuhan pengguna | D18: Akses untuk PM | E18: 1 | F18: 25 | G18: =15*7 -> 105 | H18: =G18*12 -> 1260 | I18: =H18*3 -> 3780
B19: Google Notebook Pro | C19: Menganalisa kumpulan data pasar, kebutuhan dan umpan balik pengguna | D19: Akses untuk PM | E19: 1 | F19: 30 | G19: =E19*F19 -> 30 | H19: =G19*12 -> 360 | I19: =H19*3 -> 1080
B20: Design & User Research | G20: =sum(G21:G23) -> 540 | H20: =G20*12 -> 6480 | I20: =H20*3 -> 19440
B21: Figma | C21: Membuat user flow hingga prototype | D21: Akses untuk PM, UXUI, Front End, QA | E21: 4 | F21: 30 | G21: =E21*F21 -> 120 | H21: =G21*12 -> 1440 | I21: =H21*3 -> 4320
B22: Miro | C22: Brainstorming bersama tim | D22: Akses untuk semua anggota | E22: 8 | F22: 20 | G22: =E22*F22 -> 160 | H22: =G22*12 -> 1920 | I22: =H22*3 -> 5760
B23: Maze | C23: Menjalankan uji coba pengguna dengan melihat heatmaps penggunaan prototype | D23: Akses untuk PM dan UXUI | E23: 2 | F23: 130 | G23: =E23*F23 -> 260 | H23: =G23*12 -> 3120 | I23: =H23*3 -> 9360
B24: Software Engineering | G24: =sum(G25:G28) -> 95 | H24: =G24*12 -> 1140 | I24: =H24*3 -> 3420
B25: GitHub | C25: Mengelola kode | D25: Akses untuk FE dan BE | E25: 2 | F25: 20 | G25: =E25*F25 -> 40 | H25: =G25*12 -> 480 | I25: =H25*3 -> 1440
B26: VS Code | C26: Menulis kode | D26: Akses untuk FE dan BE | E26: 2 | F26: 0 | G26: =E26*F26 -> 0 | H26: =G26*12 -> 0 | I26: =H26*3 -> 0
B27: Docker | C27: Menyatukan aplikasi untuk memudahkan ujicoba dan produksi | D27: Akses untuk FE dan BE | E27: 2 | F27: 20 | G27: =E27*F27 -> 40 | H27: =G27*12 -> 480 | I27: =H27*3 -> 1440
B28: LaunchDarkly | C28: Menandai fitur yang belum siap ujicoba | D28: Akses untuk FE dan BE | E28: 1 | F28: 15 | G28: =E28*F28 -> 15 | H28: =G28*12 -> 180 | I28: =H28*3 -> 540
B29: QA | G29: =sum(G30:G32) -> 160 | H29: =G29*12 -> 1920 | I29: =H29*3 -> 5760
B30: Postman | C30: Ujicoba API dan backend | D30: Akses untuk QA | E30: 1 | F30: 40 | G30: =E30*F30 -> 40 | H30: =G30*12 -> 480 | I30: =H30*3 -> 1440
B31: Selenium | C31: Ujicoba otomatis | D31: Akses untuk QA | E31: 1 | F31: 0 | G31: =E31*F31 -> 0 | H31: =G31*12 -> 0 | I31: =H31*3 -> 0
B32: BrowserStack | C32: Ujicoba perilaku aplikasi | D32: Akses untuk FE, BE, QA | E32: 3 | F32: 40 | G32: =E32*F32 -> 120 | H32: =G32*12 -> 1440 | I32: =H32*3 -> 4320
B33: Data Analytic | G33: =sum(G34:G35) -> 760 | H33: =G33*12 -> 9120 | I33: =H33*3 -> 27360
B34: Amplitude | C34: Pemantauan navigasi aplikasi yang dilakukan pengguna | D34: Akses untuk semua anggota | E34: 7 | F34: 80 | G34: =E34*F34 -> 560 | H34: =G34*12 -> 6720 | I34: =H34*3 -> 20160
B35: LogRocket | C35: Pemantauan kinerja sistem | D35: Akses untuk semua anggota (harga tim) | E35: 1 | F35: 200 | G35: =E35*F35 -> 200 | H35: =G35*12 -> 2400 | I35: =H35*3 -> 7200
B36: Equipment | G36: =sum(G37:G38) -> 1500000 | H36: =G36*12 -> 18000000 | I36: =H36*3 -> 54000000
B37: Server | C37: Peletakkan aplikasi dan data | D37: Akses ke aplikasi | E37: 1 | F37: 1000000 | G37: =E37*F37 -> 1000000 | H37: =G37*12 -> 12000000 | I37: =H37*3 -> 36000000
B38: Domain | C38: Alamat akses aplikasi | D38: Akses ke aplikasi | E38: 1 | F38: 500000 | G38: =E38*F38 -> 500000 | H38: =G38*12 -> 6000000 | I38: =H38*3 -> 18000000

Sheet Template
B2: Nama Modul | E2: Fungsi
B7: Kebutuhan | C7: Aktivitas | D7: Jumlah | F7: Talenta | G7: Biaya | H7: Total
D8: Modul / Fungsi | E8: Pelaksana
B9: Pengumpulan Data | C9: Memberikan feedback | D9: =if(C9="Memberikan feedback",$D$2,$H$2) | F9: Komunitas | G9: =ifs(F9="Komunitas",'Biaya Talenta'!$E$4,F9="Tech Writer",'Biaya Talenta'!$E$5,F9="UIUX Designer",'Biaya Talenta'!$E$6,F9="Junior Programmer Front End",'Biaya Talenta'!$E$7, F9="Senior Programmer Back End",'Biaya Talenta'!$E$8) -> #REF! | H9: =D9*E9*G9 -> #REF!
B10: Purwarupa | C10: Membuat PRD & Testing | D10: =if(C10="Memberikan feedback",$D$2,$H$2) | F10: Tech Writer | G10: =ifs(F10="Komunitas",'Biaya Talenta'!$E$4,F10="Tech Writer",'Biaya Talenta'!$E$5,F10="UIUX Designer",'Biaya Talenta'!$E$6,F10="Junior Programmer Front End",'Biaya Talenta'!$E$7, F10="Senior Programmer Back End",'Biaya Talenta'!$E$8) -> #REF! | H10: =D10*E10*G10 -> #REF!
C11: Merancang UIUX | D11: =if(C11="Memberikan feedback",$D$2,$H$2) | F11: UIUX Designer | G11: =ifs(F11="Komunitas",'Biaya Talenta'!$E$4,F11="Tech Writer",'Biaya Talenta'!$E$5,F11="UIUX Designer",'Biaya Talenta'!$E$6,F11="Junior Programmer Front End",'Biaya Talenta'!$E$7, F11="Senior Programmer Back End",'Biaya Talenta'!$E$8) -> #REF! | H11: =D11*E11*G11 -> #REF!
C12: Memberikan feedback | D12: =if(C12="Memberikan feedback",$D$2,$H$2) | F12: Komunitas | G12: =ifs(F12="Komunitas",'Biaya Talenta'!$E$4,F12="Tech Writer",'Biaya Talenta'!$E$5,F12="UIUX Designer",'Biaya Talenta'!$E$6,F12="Junior Programmer Front End",'Biaya Talenta'!$E$7, F12="Senior Programmer Back End",'Biaya Talenta'!$E$8) -> #REF! | H12: =D12*E12*G12 -> #REF!
B13: Implementasi | C13: Membangun kode front end dan integrasi API | D13: =if(C13="Memberikan feedback",$D$2,$H$2) | F13: Junior Programmer Front End | G13: =ifs(F13="Komunitas",'Biaya Talenta'!$E$4,F13="Tech Writer",'Biaya Talenta'!$E$5,F13="UIUX Designer",'Biaya Talenta'!$E$6,F13="Junior Programmer Front End",'Biaya Talenta'!$E$7, F13="Senior Programmer Back End",'Biaya Talenta'!$E$8) -> #REF! | H13: =D13*E13*G13 -> #REF!
C14: Membangun kode back end, database, dan instalasi ke server | D14: =if(C14="Memberikan feedback",$D$2,$H$2) | F14: Senior Programmer Back End | G14: =ifs(F14="Komunitas",'Biaya Talenta'!$E$4,F14="Tech Writer",'Biaya Talenta'!$E$5,F14="UIUX Designer",'Biaya Talenta'!$E$6,F14="Junior Programmer Front End",'Biaya Talenta'!$E$7, F14="Senior Programmer Back End",'Biaya Talenta'!$E$8) -> #REF! | H14: =D14*E14*G14 -> #REF!
C15: Memberikan feedback | D15: =if(C15="Memberikan feedback",$D$2,$H$2) | F15: Komunitas | G15: =ifs(F15="Komunitas",'Biaya Talenta'!$E$4,F15="Tech Writer",'Biaya Talenta'!$E$5,F15="UIUX Designer",'Biaya Talenta'!$E$6,F15="Junior Programmer Front End",'Biaya Talenta'!$E$7, F15="Senior Programmer Back End",'Biaya Talenta'!$E$8) -> #REF! | H15: =D15*E15*G15 -> #REF!
B16: Total Anggaran | H16: =SUM(H9:H15) -> #REF!
